---
layout: post
title:  "例外処理"
date:   2019-05-04 20:07:45 +0900
categories: [Java, Japanese]
image: 1.png, 2.png, 3.png, 4.png
---

**1.例外処理(Exception handling)**
&nbsp;
**1.1 プログラムのエラー**
- コンパイルエラー(complier-time error)とランタイムエラー(runtime error)
  - コンパイルエラー - コンパイルするときに発生するエラー
  - ランタイムエラー - 実行時に発生するエラー
  - 論理的エラー - 意図と異なる結果を招く
&nbsp;
- Javaのランタイムエラー (error)と例外(exception)
  - エラー-プログラムコードによって収拾できない深刻なエラー
  - エラー(exception) - プログラムコードによって収拾できる多少微弱なエラー
&nbsp;
**1.2例外処理の定義と目的**
- エラー(error)はやむを得ないが,例外(exception)は処理しなければならない。
- 例外処理の定義と目的
- 定義:プログラムの実行時に発生できる例外の発生に備えたコードを作成すること。
- 目的:プログラムの異常終了を防ぎ,正常な実行状態を維持すること。
&nbsp;
**1.3、例外処理構文**
- 例外を処理するには,try-catch文を使用しなければならない。
&nbsp;
```java
try {
	//例外になり得る文章
	catch (Exception e) {
	//例外を処理する文章
	}
}
```
&nbsp;
**1.4 try-catch文中の流れ**
-ブロック内で例外が発生した場合。
  - 発生した例外と一致するcatchブロックがあるかどうかを確認する。
  - 一致するcatchブロックを探すようになると,そのcatchブロック内の文章を遂行して全体try-catch文を抜けてその次の文を続けて遂行する。 万一、一致するcatchブロックが見つからなければ,例外は処理されない。

   ![Screenshot broadcast](https://raw.githubusercontent.com/Bullishman/bullishman.github.io/master/static/img/_posts/%E4%BE%8B%E5%A4%96%E5%87%A6%E7%90%86/1.png "Screenshot broadcast")

- tryブロック内で例外が発生していない場合。
  - catchブロックを経ずに全体try-catch文を抜けて修行を続ける

  ![Screenshot broadcast](https://raw.githubusercontent.com/Bullishman/bullishman.github.io/master/static/img/_posts/%E4%BE%8B%E5%A4%96%E5%87%A6%E7%90%86/2.png "Screenshot broadcast")
&nbsp;
  **1.5 例外発生させる**
-まず, 演算子newを利用して発生させようとする例外クラスの客体を作った後,キーワードthrowを利用して例外を発生させる。
&nbsp;
```java
class ExceptionEx6 {
	public static void main(String[] args) {
		try {
			Exception e = new Exception ("故意で発生させた");
	  } catch (Exception e) {
			System.out.println("エラーメッセージ:"+ e.getMessage());
			e.printStackTrace();
		}
		System.out.println("プログラムが正常終了した。");
	}
}
```
&nbsp;
**1.6 例外クラスの階層構造**
-例外クラスは大きく二つのグループに分けられる。
  - Exceptionクラス:ユーザのミスのような外的な要因によって発生する例外(例外処理必須)
  - RuntimeException:プログラマーのミスで発生する例外(例外処理選択)

     ![Screenshot broadcast](https://raw.githubusercontent.com/Bullishman/bullishman.github.io/master/static/img/_posts/%E4%BE%8B%E5%A4%96%E5%87%A6%E7%90%86/3.png "Screenshot broadcast")
&nbsp;
  **1.7、例外の発生とcatchブロック(1/2)**
  - tryブロックで例外が発生すると,発生した例外を処理するcatchブロックを探す。
  - 最初のcatchブロックから順に訪れて、下がりながら、一致するcatchブロックがなければ例外は、処理されていない。
  - 例外の最高先祖であるExceptionを処理するcatchブロックは,あらゆる種類の例外を処理することができる。 必ず最後のcatch ブロックでなければならない
&nbsp;
  ```java
  class ExceptionEx11 {
  	public static void main {
  		System.out.println(1);
  		System.out.println(2);
  		try {
  			System.out.println(3);
  			System.out.println(0/0);
  			System.out.println(4);
      } catch (ArithmeticException ae) {
			     if (ae instanceof ArithmeticException);
				       System.out.println("true");
			         System.out.println("ArithmeticException");
		  } catch (Exception e) {
			     System.out.println("Exception");
		  } // try-catchの端
  		  System.out.println(6);
  	}	// メインメソッドの終り
  }
  ```
&nbsp;
  **1.7 例外の発生とcatchブロック(2/2)**
  - 発生した例外オブジェクトをcatchブロックの参照変数としてアクセスできる。
  - printStrackTrace(): 例外発生当時の呼び出しスタックにあったメサードの情報と,例外メッセージを画面に出力する。
  - getMessage(): 発生した例外クラスのインスタンスに保存されたメッセージを得ることができる。
&nbsp;
  ```java
  class ExceptionEx12 {
  	public static void main {
  		System.out.println(1);
  		System.out.println(2);
  		try {
  			System.out.println(3);
  			System.out.println(0/0);
  			System.out.println(4);
  		} catch (ArithmeticException ae) {
			     ae.printStackTrace();
			        if (ae instanceof ArithmeticException);
  		          System.out.println("例外メッセージ:" + ae.getMessage);
		  } // try-catchの端
  		System.out.println(6);
  	  // メインメソッドの終り
  }
}
  ```
&nbsp;
  **1.8 finallyブロック**
  - 例外の発生有無に関わらず,実行されるべきコードを入れる。
  - 選択的に使用でき,try-catch-finallyの手順で構成される。
  - 例外発生時, try → catch → finallyの順に実行され
  - 例外未発生時,try → finallyの順に実行される。
  - tryまたはcatchブロックでreturn文に会ってもfinallyブロックは実行される。
```java
  try {
  	// 例外が生じる可能性のある文章を入れる。
  } catch {
  	// 例外処理のための文章を書く。
  } finally {
  	// 例外の発生の有無に関係なく常に遂行されなければならない文章
  	// finallyブロックはtry-catch文の最後尾に位置しなければならない。
  }
```
&nbsp;
  **1.9・メソッドに例外宣言する**
  - 例外を処理するもう一つの方法
  - 実は例外を処理するのではなく,呼び出したメソドに伝達すること
  - 呼び出したメソッドで例外処理をしなければならない時に使用
&nbsp;
  ```java
  void method Exception、Exception2、…...... ExceptionN
  	//メソッドの内容
  }
  ```
&nbsp;
  **1.9 メソッドに例外宣言する–例題**
  &nbsp;
  ```java
  class ExceptionEx18 {
  	public static void main(String[] throws Exception {
  		method1(); // 同じクラス内のstaticのメンバーであるため、オブジェクト生成なく、直接呼び出し可能
  	}

  	static void method1()throws Exception {
  		method2();
  		//method1の最後
  	}

  	static void method2()throws Exception{
  		throw new Exception
  		//method2の最後
  	}
  }
  ```
  &nbsp;
     ![Screenshot broadcast](https://raw.githubusercontent.com/Bullishman/bullishman.github.io/master/static/img/_posts/%E4%BE%8B%E5%A4%96%E5%87%A6%E7%90%86/4.png "Screenshot broadcast")
&nbsp;
  **1.9・メソッドに例外宣言する–の例2**
&nbsp;
  ```java
  class ExceptionEx21{
  	public static void main {
  		// command line で入力された値を名前で持つファイルを生成する。
  		File f = createFile(args[0]);
  		System.out.println(f.getName)+"ファイルが成功裏に生成されました。");
  	}

  	static File createFile(String fileName) {
  		try {
  			if (fileName == null || fileName.equals(""))
  				throw new Exception("ファイル");ファイル名が有効しない
  		} catch (Exception e) {)
  			// fileNameが不適切な場合,ファイル名を'タイトルなし.txt'とする。
  			fileName='題目なし.txt';
  		} finally {
  			File f = new File(fileName);
  			createNewFile(f);
  			return f;
  		}
  	}

  	static void createNewFile(File f) {
  		try {
  			f.createNewFile();
  		} catch (IOException e) { }
  	}
  }
  ```
&nbsp;
  **1.9・メソッドに例外宣言する–例題3**
&nbsp;
  ```java
  class ExceptionEx22 {
  	public static void main(String[] args) {
  		try {
  			File f = createFile(args[0]);
  			System.out.println(f.getName()+"ファイルが成功的に生成されました");
  		} catch (Exception e) {
  			System.out.println((e.getMessage)+ "再び入力してください")
  		}
  	}

  	static File createFile(String fileName) throws Exception {
  		if (fileName=null || fileName.equals(""))
  			throw new Exception;
  		File f = new File(fileName);// Fileクラスのオブジェクトを作る。
  		// Fileオブジェクトの createNewFileメソッドを利用して実際のファイルを生成する。
  		f.createNewFile();
  		return f;
  	}
  }
  ```
&nbsp;
  **1.10例外投げ返し(re-throwing)**
  - 例外を処理した後,再び例外を生成して呼び出したメソッドを伝えること
  - 例外が発生したメソッドと呼び出したメソッド,両方で例外を処理しなければならない場合に使用。
&nbsp;
  **1.11ユーザ定義例外する**
  -既存の例外クラスを相続受けて新しい例外クラスを定義することができる。
  ```java
  class MyException extends Exception
  	MyException(String msg) { // 文字列を媒介変数で受ける生成者
  		super(msg); // 先祖のExceptionクラスの生成者を呼び出す。
  	}
  } 
  ```
  &nbsp;
  - エラーコードを保存できるようにERR_CODEとgetErrcode()をメンバーに追加
  ```java
  class MyException extends Exception {
  	private final int ERR_CODE

  	MyException(String msg,int errCode) { //生成子
  		Super;
  		ERR_CODE= errCode;
  	}

  	MyException(String msg){//生成子
  		this(msg、100);		//ERR_CODEを100(基本値)に、初期化する。
  	}

  	public int getErrCode() { // エラーコードが得られるメソッドも追加した。
  		return ER_CODE; // このメソッドは主に getMessage()と共に使われるだろう。
  	}
  }
  ```
